<mujoco model="unnamed_model">
  <compiler autolimits="true" angle="radian"/>
  <option timestep="0.002" impratio="100" o_solref="1.0000000000000001e-09 1" o_solimp="0.001 1" integrator="implicitfast" cone="pyramidal" solver="Newton">
    <flag override="enable" multiccd="enable"/>
  </option>
  <size memory="1000M"/>
  <visual>
    <global azimuth="-120" elevation="-20" offwidth="640" offheight="640"/>
  </visual>
  <statistic meansize="0.080000000000000002"/>
  <default>
    <default class="/"/>
    <default class="l_robot/">
      <default class="l_robot/panda">
        <material specular="0.5" shininess="0.25"/>
        <joint axis="0 0 1" range="-2.8973 2.8973" armature="0.10000000000000001" damping="1"/>
        <general ctrlrange="-2.8973 2.8973" forcerange="-87 87" dyntype="none" biastype="affine"/>
        <default class="l_robot/finger">
          <joint type="slide" axis="0 1 0" range="0 0.040000000000000001"/>
        </default>
        <default class="l_robot/visual">
          <geom type="mesh" contype="0" conaffinity="0" group="2"/>
        </default>
        <default class="l_robot/collision">
          <geom type="mesh" group="3"/>
          <default class="l_robot/fingertip_pad_collision_1">
            <geom type="box" condim="4" size="0.0085000000000000006 0.0040000000000000001 0.0085000000000000006" rgba="1 0 0 1" friction="1 1 1" pos="0 0.0037000000000000002 0.044499999999999998"/>
          </default>
          <default class="l_robot/fingertip_pad_collision_2">
            <geom type="box" condim="4" size="0.0030000000000000001 0.002 0.0030000000000000001" rgba="0 1 0 1" friction="1 1 1" pos="0.0054999999999999997 0.002 0.050000000000000003"/>
          </default>
          <default class="l_robot/fingertip_pad_collision_3">
            <geom type="box" condim="4" size="0.0030000000000000001 0.002 0.0030000000000000001" friction="1 1 1" pos="-0.0054999999999999997 0.002 0.050000000000000003"/>
          </default>
          <default class="l_robot/fingertip_pad_collision_4">
            <geom type="box" condim="4" size="0.0030000000000000001 0.002 0.0035000000000000001" friction="1 1 1" pos="0.0054999999999999997 0.002 0.0395"/>
          </default>
          <default class="l_robot/fingertip_pad_collision_5">
            <geom type="box" condim="4" size="0.0030000000000000001 0.002 0.0035000000000000001" friction="1 1 1" pos="-0.0054999999999999997 0.002 0.0395"/>
          </default>
        </default>
      </default>
    </default>
    <default class="r_robot/">
      <default class="r_robot/panda">
        <material specular="0.5" shininess="0.25"/>
        <joint axis="0 0 1" range="-2.8973 2.8973" armature="0.10000000000000001" damping="1"/>
        <general ctrlrange="-2.8973 2.8973" forcerange="-87 87" dyntype="none" biastype="affine"/>
        <default class="r_robot/finger">
          <joint type="slide" axis="0 1 0" range="0 0.040000000000000001"/>
        </default>
        <default class="r_robot/visual">
          <geom type="mesh" contype="0" conaffinity="0" group="2"/>
        </default>
        <default class="r_robot/collision">
          <geom type="mesh" group="3"/>
          <default class="r_robot/fingertip_pad_collision_1">
            <geom type="box" condim="4" size="0.0085000000000000006 0.0040000000000000001 0.0085000000000000006" rgba="1 0 0 1" friction="1 1 1" pos="0 0.0037000000000000002 0.044499999999999998"/>
          </default>
          <default class="r_robot/fingertip_pad_collision_2">
            <geom type="box" condim="4" size="0.0030000000000000001 0.002 0.0030000000000000001" rgba="0 1 0 1" friction="1 1 1" pos="0.0054999999999999997 0.002 0.050000000000000003"/>
          </default>
          <default class="r_robot/fingertip_pad_collision_3">
            <geom type="box" condim="4" size="0.0030000000000000001 0.002 0.0030000000000000001" friction="1 1 1" pos="-0.0054999999999999997 0.002 0.050000000000000003"/>
          </default>
          <default class="r_robot/fingertip_pad_collision_4">
            <geom type="box" condim="4" size="0.0030000000000000001 0.002 0.0035000000000000001" friction="1 1 1" pos="0.0054999999999999997 0.002 0.0395"/>
          </default>
          <default class="r_robot/fingertip_pad_collision_5">
            <geom type="box" condim="4" size="0.0030000000000000001 0.002 0.0035000000000000001" friction="1 1 1" pos="-0.0054999999999999997 0.002 0.0395"/>
          </default>
        </default>
      </default>
    </default>
    <default class="bimanual_insertion_peg/">
      <default class="bimanual_insertion_peg/visual">
        <geom type="mesh" contype="0" conaffinity="0" group="2"/>
      </default>
      <default class="bimanual_insertion_peg/collision">
        <geom type="mesh" condim="4" group="3" friction="10 10 10"/>
      </default>
    </default>
    <default class="bimanual_insertion_hole3/">
      <default class="bimanual_insertion_hole3/visual">
        <geom type="mesh" contype="0" conaffinity="0" group="2"/>
      </default>
      <default class="bimanual_insertion_hole3/collision">
        <geom type="mesh" condim="4" group="3" friction="10 10 10"/>
      </default>
    </default>
  </default>
  <asset>
    <texture name="grid" type="2d" builtin="checker" rgb1="0.20000000000000001 0.29999999999999999 0.40000000000000002" rgb2="0.10000000000000001 0.20000000000000001 0.29999999999999999" mark="cross" markrgb="0 0 0" width="256" height="256"/>
    <material name="grid" class="/" texture="grid" texrepeat="1 1" texuniform="true"/>
    <material name="l_robot/white" class="l_robot/panda" specular="0.10000000000000001" shininess="0.40000000000000002" reflectance="0.20000000000000001" rgba="1 1 1 1"/>
    <material name="l_robot/off_white" class="l_robot/panda" specular="0.10000000000000001" shininess="0.40000000000000002" reflectance="0.20000000000000001" rgba="0.90196100000000001 0.92156899999999997 0.92941200000000002 1"/>
    <material name="l_robot/black" class="l_robot/panda" specular="0.10000000000000001" shininess="0.40000000000000002" reflectance="0.20000000000000001" rgba="0.25 0.25 0.25 1"/>
    <material name="l_robot/green" class="l_robot/panda" specular="0.10000000000000001" shininess="0.40000000000000002" reflectance="0.20000000000000001" rgba="0 1 0 1"/>
    <material name="l_robot/light_blue" class="l_robot/panda" specular="0.10000000000000001" shininess="0.40000000000000002" reflectance="0.20000000000000001" rgba="0.039216000000000001 0.54117599999999999 0.78039199999999997 1"/>
    <mesh name="l_robot/link0_c" class="l_robot/" file="link0-3f633d19409870795516c6de40b4c7922f53c43d.stl"/>
    <mesh name="l_robot/link1_c" class="l_robot/" file="link1-53f934209b6019b996b6d9c714d0a9cf102f7fb2.stl"/>
    <mesh name="l_robot/link2_c" class="l_robot/" file="link2-8500c695b73e8ceeaa520c02db5684f02793b80f.stl"/>
    <mesh name="l_robot/link3_c" class="l_robot/" file="link3-0af960563df21dd3a3b0afac6e34f62bf10c71c4.stl"/>
    <mesh name="l_robot/link4_c" class="l_robot/" file="link4-97c9a53ee35f3939b3438a38005e78fd4c9f23cb.stl"/>
    <mesh name="l_robot/link5_c0" class="l_robot/" file="link5_collision_0-f402b8885893e833c27f7eca01b669b81476a48f.obj"/>
    <mesh name="l_robot/link5_c1" class="l_robot/" file="link5_collision_1-3735bde5d4211e2d565b9cc20b919f55e697be05.obj"/>
    <mesh name="l_robot/link5_c2" class="l_robot/" file="link5_collision_2-585e84d1d7e381827b73c7ecd50f2010775235c9.obj"/>
    <mesh name="l_robot/link6_c" class="l_robot/" file="link6-e9fa3ad660cf2a9b04e0ec55e8d56abf5891d531.stl"/>
    <mesh name="l_robot/link7_c" class="l_robot/" file="link7-5dcc7199c8e231447ebda37651ead64ebe3cf6ec.stl"/>
    <mesh name="l_robot/hand_c" class="l_robot/" file="hand-56394d6e04b1579484cd4323dc50c3240332cfe2.stl"/>
    <mesh name="l_robot/link0_0" class="l_robot/" file="link0_0-b7cf6e228cebc1309b79491310541fe8a60e2d62.obj"/>
    <mesh name="l_robot/link0_1" class="l_robot/" file="link0_1-5ecc0c585f0d6a4207ba87f6aeed2df5632b2ebe.obj"/>
    <mesh name="l_robot/link0_2" class="l_robot/" file="link0_2-88529048e478fb7cca6eeeaaa0405b00ca337c0a.obj"/>
    <mesh name="l_robot/link0_3" class="l_robot/" file="link0_3-75c03dfe4002c399dfeaea609db33c25ae42f82f.obj"/>
    <mesh name="l_robot/link0_4" class="l_robot/" file="link0_4-6917a10a52309fc722169515f143ac9bd6a2b084.obj"/>
    <mesh name="l_robot/link0_5" class="l_robot/" file="link0_5-8d54ecd0c38e0b412ac31ef46675fdca7e0e4717.obj"/>
    <mesh name="l_robot/link0_7" class="l_robot/" file="link0_7-79cbcc01643937964f9e547e9b3d225888aa50c7.obj"/>
    <mesh name="l_robot/link0_8" class="l_robot/" file="link0_8-4c89da97ea30fff7777d1a961c922a48425291ef.obj"/>
    <mesh name="l_robot/link0_9" class="l_robot/" file="link0_9-776b30016c2bb8f206d560786910bfccb809926d.obj"/>
    <mesh name="l_robot/link0_10" class="l_robot/" file="link0_10-d7b529ebc6940c0415ad91e938b0c39f05853d07.obj"/>
    <mesh name="l_robot/link0_11" class="l_robot/" file="link0_11-46418d08940dd95e72b8290253d6bfb37aa3ba10.obj"/>
    <mesh name="l_robot/link1" class="l_robot/" file="link1-ed231c089447a0928504d8a0b6d31c196f6f4b28.obj"/>
    <mesh name="l_robot/link2" class="l_robot/" file="link2-21fdd1eb16bc9d11a5349b39cc21c9ecafff6cb2.obj"/>
    <mesh name="l_robot/link3_0" class="l_robot/" file="link3_0-644740d89be54fee424dac34a096ed07f0c0be9a.obj"/>
    <mesh name="l_robot/link3_1" class="l_robot/" file="link3_1-aa5980b7ffb0ff37d6f81bf5d03cca87b4182c72.obj"/>
    <mesh name="l_robot/link3_2" class="l_robot/" file="link3_2-41efc81a33bb7585a8676c163e2d66ac5cc1fbb5.obj"/>
    <mesh name="l_robot/link3_3" class="l_robot/" file="link3_3-c433c61f6a518e2810fa405a084aa55ae95bc09c.obj"/>
    <mesh name="l_robot/link4_0" class="l_robot/" file="link4_0-70b359cb835f79b58037732ffb174c30589ca379.obj"/>
    <mesh name="l_robot/link4_1" class="l_robot/" file="link4_1-8a206f8e5eee869db6b4d9e77db083f6edbc5e6b.obj"/>
    <mesh name="l_robot/link4_2" class="l_robot/" file="link4_2-5c5b38db50c3864953a5ee4766d35f5fae84e0dc.obj"/>
    <mesh name="l_robot/link4_3" class="l_robot/" file="link4_3-46cdfe6cf343836b30218551cd40c45197cd3f7d.obj"/>
    <mesh name="l_robot/link5_0" class="l_robot/" file="link5_0-c9c057e806e8a7919fb33f70114229b6d3c40dcd.obj"/>
    <mesh name="l_robot/link5_1" class="l_robot/" file="link5_1-f07ba3f01e7be86042be33cef54249a02bd73749.obj"/>
    <mesh name="l_robot/link5_2" class="l_robot/" file="link5_2-fc227a4bf91b7bc23a55448c810557f391f1d5e3.obj"/>
    <mesh name="l_robot/link6_0" class="l_robot/" file="link6_0-6836f8b697cf67e536dc9bbd5fa9250c58c12ca7.obj"/>
    <mesh name="l_robot/link6_1" class="l_robot/" file="link6_1-d0da79111a0c81081fcdfa01fb58586c92d8322d.obj"/>
    <mesh name="l_robot/link6_2" class="l_robot/" file="link6_2-d6b659cb277c78c300d62cdb6449eaaa8814b5d2.obj"/>
    <mesh name="l_robot/link6_3" class="l_robot/" file="link6_3-ba09733138cd64d0a7366ffe1385267da3597481.obj"/>
    <mesh name="l_robot/link6_4" class="l_robot/" file="link6_4-32e7cb101a33786176152037acd0a8872e7d5ad5.obj"/>
    <mesh name="l_robot/link6_5" class="l_robot/" file="link6_5-38d0c1ecd191ee8d914ba6b7a6afa271432c665f.obj"/>
    <mesh name="l_robot/link6_6" class="l_robot/" file="link6_6-5ed9d943e4d2c63735b56d3e3635a3a07c6470db.obj"/>
    <mesh name="l_robot/link6_7" class="l_robot/" file="link6_7-106080e92cb497bc3906f4e5ee2f49fd62ea7f89.obj"/>
    <mesh name="l_robot/link6_8" class="l_robot/" file="link6_8-bbfe67149c4cfd9d81968a91844069d474f53f2d.obj"/>
    <mesh name="l_robot/link6_9" class="l_robot/" file="link6_9-09876ce72bf2f306c3ac7005f461a2d88f78dccd.obj"/>
    <mesh name="l_robot/link6_10" class="l_robot/" file="link6_10-b0430678bf45d2dcb5a064b8a19f1f93945864fb.obj"/>
    <mesh name="l_robot/link6_11" class="l_robot/" file="link6_11-dbcbe820a516782674773335ffc26931de719df1.obj"/>
    <mesh name="l_robot/link6_12" class="l_robot/" file="link6_12-7f56f8ec4561cb5b724ff00e00d6f0efe8bf7123.obj"/>
    <mesh name="l_robot/link6_13" class="l_robot/" file="link6_13-a0d4d39ca68ff2ec5a17977ecc13dc02b5b4fdd2.obj"/>
    <mesh name="l_robot/link6_14" class="l_robot/" file="link6_14-fde4741db758169025860d9d06157c80aab9f9c0.obj"/>
    <mesh name="l_robot/link6_15" class="l_robot/" file="link6_15-5e7addd48c4088cfeb5280ef77bc69e4cdb45939.obj"/>
    <mesh name="l_robot/link6_16" class="l_robot/" file="link6_16-d583372e8c9632ad1aa003ef6c5ac09effbf2102.obj"/>
    <mesh name="l_robot/link7_0" class="l_robot/" file="link7_0-2e4ca001c5c670d1e7b84e342df95cc1b01ee137.obj"/>
    <mesh name="l_robot/link7_1" class="l_robot/" file="link7_1-3dfe858021e5f7d422c2f51e5663f07272b758fc.obj"/>
    <mesh name="l_robot/link7_2" class="l_robot/" file="link7_2-2643e68c73e2988b9f66992bdd9ea846cae1e128.obj"/>
    <mesh name="l_robot/link7_3" class="l_robot/" file="link7_3-9eff475605fd7c4d72ff0031ee375b7bab95920b.obj"/>
    <mesh name="l_robot/link7_4" class="l_robot/" file="link7_4-6ea88c0c0f5a79079aa03008291a9df01ea43ed5.obj"/>
    <mesh name="l_robot/link7_5" class="l_robot/" file="link7_5-916ac62d00e858d819cb553fe73db314185cdd47.obj"/>
    <mesh name="l_robot/link7_6" class="l_robot/" file="link7_6-9d637adbf9ceabb0d5f85515c03d065c54fde3dc.obj"/>
    <mesh name="l_robot/link7_7" class="l_robot/" file="link7_7-652eee34bbafccbee18e5c1c8f96823fcaaf242d.obj"/>
    <mesh name="l_robot/hand_0" class="l_robot/" file="hand_0-cfe318371d80d790934fba8bf6b6fb7f64071ac6.obj"/>
    <mesh name="l_robot/hand_1" class="l_robot/" file="hand_1-7cd93918f5bc964665658b0af0ff92876fe9a85d.obj"/>
    <mesh name="l_robot/hand_2" class="l_robot/" file="hand_2-9aff904f0b08a77437e7894da1d4efc4d4a52059.obj"/>
    <mesh name="l_robot/hand_3" class="l_robot/" file="hand_3-9909795ec9ec03e824cbb49691c32a4366fb2f4d.obj"/>
    <mesh name="l_robot/hand_4" class="l_robot/" file="hand_4-8a7602e34e1ed3ddacdaa10cf857f811276d4a2c.obj"/>
    <mesh name="l_robot/finger_0" class="l_robot/" file="finger_0-cf20576acd5b52daef643d398ae3b30fee1027d3.obj"/>
    <mesh name="l_robot/finger_1" class="l_robot/" file="finger_1-87276f8cb602e3141fccda3eb9b263c18fba3fe1.obj"/>
    <material name="r_robot/white" class="r_robot/panda" specular="0.10000000000000001" shininess="0.40000000000000002" reflectance="0.20000000000000001" rgba="1 1 1 1"/>
    <material name="r_robot/off_white" class="r_robot/panda" specular="0.10000000000000001" shininess="0.40000000000000002" reflectance="0.20000000000000001" rgba="0.90196100000000001 0.92156899999999997 0.92941200000000002 1"/>
    <material name="r_robot/black" class="r_robot/panda" specular="0.10000000000000001" shininess="0.40000000000000002" reflectance="0.20000000000000001" rgba="0.25 0.25 0.25 1"/>
    <material name="r_robot/green" class="r_robot/panda" specular="0.10000000000000001" shininess="0.40000000000000002" reflectance="0.20000000000000001" rgba="0 1 0 1"/>
    <material name="r_robot/light_blue" class="r_robot/panda" specular="0.10000000000000001" shininess="0.40000000000000002" reflectance="0.20000000000000001" rgba="0.039216000000000001 0.54117599999999999 0.78039199999999997 1"/>
    <mesh name="r_robot/link0_c" class="r_robot/" file="link0-3f633d19409870795516c6de40b4c7922f53c43d.stl"/>
    <mesh name="r_robot/link1_c" class="r_robot/" file="link1-53f934209b6019b996b6d9c714d0a9cf102f7fb2.stl"/>
    <mesh name="r_robot/link2_c" class="r_robot/" file="link2-8500c695b73e8ceeaa520c02db5684f02793b80f.stl"/>
    <mesh name="r_robot/link3_c" class="r_robot/" file="link3-0af960563df21dd3a3b0afac6e34f62bf10c71c4.stl"/>
    <mesh name="r_robot/link4_c" class="r_robot/" file="link4-97c9a53ee35f3939b3438a38005e78fd4c9f23cb.stl"/>
    <mesh name="r_robot/link5_c0" class="r_robot/" file="link5_collision_0-f402b8885893e833c27f7eca01b669b81476a48f.obj"/>
    <mesh name="r_robot/link5_c1" class="r_robot/" file="link5_collision_1-3735bde5d4211e2d565b9cc20b919f55e697be05.obj"/>
    <mesh name="r_robot/link5_c2" class="r_robot/" file="link5_collision_2-585e84d1d7e381827b73c7ecd50f2010775235c9.obj"/>
    <mesh name="r_robot/link6_c" class="r_robot/" file="link6-e9fa3ad660cf2a9b04e0ec55e8d56abf5891d531.stl"/>
    <mesh name="r_robot/link7_c" class="r_robot/" file="link7-5dcc7199c8e231447ebda37651ead64ebe3cf6ec.stl"/>
    <mesh name="r_robot/hand_c" class="r_robot/" file="hand-56394d6e04b1579484cd4323dc50c3240332cfe2.stl"/>
    <mesh name="r_robot/link0_0" class="r_robot/" file="link0_0-b7cf6e228cebc1309b79491310541fe8a60e2d62.obj"/>
    <mesh name="r_robot/link0_1" class="r_robot/" file="link0_1-5ecc0c585f0d6a4207ba87f6aeed2df5632b2ebe.obj"/>
    <mesh name="r_robot/link0_2" class="r_robot/" file="link0_2-88529048e478fb7cca6eeeaaa0405b00ca337c0a.obj"/>
    <mesh name="r_robot/link0_3" class="r_robot/" file="link0_3-75c03dfe4002c399dfeaea609db33c25ae42f82f.obj"/>
    <mesh name="r_robot/link0_4" class="r_robot/" file="link0_4-6917a10a52309fc722169515f143ac9bd6a2b084.obj"/>
    <mesh name="r_robot/link0_5" class="r_robot/" file="link0_5-8d54ecd0c38e0b412ac31ef46675fdca7e0e4717.obj"/>
    <mesh name="r_robot/link0_7" class="r_robot/" file="link0_7-79cbcc01643937964f9e547e9b3d225888aa50c7.obj"/>
    <mesh name="r_robot/link0_8" class="r_robot/" file="link0_8-4c89da97ea30fff7777d1a961c922a48425291ef.obj"/>
    <mesh name="r_robot/link0_9" class="r_robot/" file="link0_9-776b30016c2bb8f206d560786910bfccb809926d.obj"/>
    <mesh name="r_robot/link0_10" class="r_robot/" file="link0_10-d7b529ebc6940c0415ad91e938b0c39f05853d07.obj"/>
    <mesh name="r_robot/link0_11" class="r_robot/" file="link0_11-46418d08940dd95e72b8290253d6bfb37aa3ba10.obj"/>
    <mesh name="r_robot/link1" class="r_robot/" file="link1-ed231c089447a0928504d8a0b6d31c196f6f4b28.obj"/>
    <mesh name="r_robot/link2" class="r_robot/" file="link2-21fdd1eb16bc9d11a5349b39cc21c9ecafff6cb2.obj"/>
    <mesh name="r_robot/link3_0" class="r_robot/" file="link3_0-644740d89be54fee424dac34a096ed07f0c0be9a.obj"/>
    <mesh name="r_robot/link3_1" class="r_robot/" file="link3_1-aa5980b7ffb0ff37d6f81bf5d03cca87b4182c72.obj"/>
    <mesh name="r_robot/link3_2" class="r_robot/" file="link3_2-41efc81a33bb7585a8676c163e2d66ac5cc1fbb5.obj"/>
    <mesh name="r_robot/link3_3" class="r_robot/" file="link3_3-c433c61f6a518e2810fa405a084aa55ae95bc09c.obj"/>
    <mesh name="r_robot/link4_0" class="r_robot/" file="link4_0-70b359cb835f79b58037732ffb174c30589ca379.obj"/>
    <mesh name="r_robot/link4_1" class="r_robot/" file="link4_1-8a206f8e5eee869db6b4d9e77db083f6edbc5e6b.obj"/>
    <mesh name="r_robot/link4_2" class="r_robot/" file="link4_2-5c5b38db50c3864953a5ee4766d35f5fae84e0dc.obj"/>
    <mesh name="r_robot/link4_3" class="r_robot/" file="link4_3-46cdfe6cf343836b30218551cd40c45197cd3f7d.obj"/>
    <mesh name="r_robot/link5_0" class="r_robot/" file="link5_0-c9c057e806e8a7919fb33f70114229b6d3c40dcd.obj"/>
    <mesh name="r_robot/link5_1" class="r_robot/" file="link5_1-f07ba3f01e7be86042be33cef54249a02bd73749.obj"/>
    <mesh name="r_robot/link5_2" class="r_robot/" file="link5_2-fc227a4bf91b7bc23a55448c810557f391f1d5e3.obj"/>
    <mesh name="r_robot/link6_0" class="r_robot/" file="link6_0-6836f8b697cf67e536dc9bbd5fa9250c58c12ca7.obj"/>
    <mesh name="r_robot/link6_1" class="r_robot/" file="link6_1-d0da79111a0c81081fcdfa01fb58586c92d8322d.obj"/>
    <mesh name="r_robot/link6_2" class="r_robot/" file="link6_2-d6b659cb277c78c300d62cdb6449eaaa8814b5d2.obj"/>
    <mesh name="r_robot/link6_3" class="r_robot/" file="link6_3-ba09733138cd64d0a7366ffe1385267da3597481.obj"/>
    <mesh name="r_robot/link6_4" class="r_robot/" file="link6_4-32e7cb101a33786176152037acd0a8872e7d5ad5.obj"/>
    <mesh name="r_robot/link6_5" class="r_robot/" file="link6_5-38d0c1ecd191ee8d914ba6b7a6afa271432c665f.obj"/>
    <mesh name="r_robot/link6_6" class="r_robot/" file="link6_6-5ed9d943e4d2c63735b56d3e3635a3a07c6470db.obj"/>
    <mesh name="r_robot/link6_7" class="r_robot/" file="link6_7-106080e92cb497bc3906f4e5ee2f49fd62ea7f89.obj"/>
    <mesh name="r_robot/link6_8" class="r_robot/" file="link6_8-bbfe67149c4cfd9d81968a91844069d474f53f2d.obj"/>
    <mesh name="r_robot/link6_9" class="r_robot/" file="link6_9-09876ce72bf2f306c3ac7005f461a2d88f78dccd.obj"/>
    <mesh name="r_robot/link6_10" class="r_robot/" file="link6_10-b0430678bf45d2dcb5a064b8a19f1f93945864fb.obj"/>
    <mesh name="r_robot/link6_11" class="r_robot/" file="link6_11-dbcbe820a516782674773335ffc26931de719df1.obj"/>
    <mesh name="r_robot/link6_12" class="r_robot/" file="link6_12-7f56f8ec4561cb5b724ff00e00d6f0efe8bf7123.obj"/>
    <mesh name="r_robot/link6_13" class="r_robot/" file="link6_13-a0d4d39ca68ff2ec5a17977ecc13dc02b5b4fdd2.obj"/>
    <mesh name="r_robot/link6_14" class="r_robot/" file="link6_14-fde4741db758169025860d9d06157c80aab9f9c0.obj"/>
    <mesh name="r_robot/link6_15" class="r_robot/" file="link6_15-5e7addd48c4088cfeb5280ef77bc69e4cdb45939.obj"/>
    <mesh name="r_robot/link6_16" class="r_robot/" file="link6_16-d583372e8c9632ad1aa003ef6c5ac09effbf2102.obj"/>
    <mesh name="r_robot/link7_0" class="r_robot/" file="link7_0-2e4ca001c5c670d1e7b84e342df95cc1b01ee137.obj"/>
    <mesh name="r_robot/link7_1" class="r_robot/" file="link7_1-3dfe858021e5f7d422c2f51e5663f07272b758fc.obj"/>
    <mesh name="r_robot/link7_2" class="r_robot/" file="link7_2-2643e68c73e2988b9f66992bdd9ea846cae1e128.obj"/>
    <mesh name="r_robot/link7_3" class="r_robot/" file="link7_3-9eff475605fd7c4d72ff0031ee375b7bab95920b.obj"/>
    <mesh name="r_robot/link7_4" class="r_robot/" file="link7_4-6ea88c0c0f5a79079aa03008291a9df01ea43ed5.obj"/>
    <mesh name="r_robot/link7_5" class="r_robot/" file="link7_5-916ac62d00e858d819cb553fe73db314185cdd47.obj"/>
    <mesh name="r_robot/link7_6" class="r_robot/" file="link7_6-9d637adbf9ceabb0d5f85515c03d065c54fde3dc.obj"/>
    <mesh name="r_robot/link7_7" class="r_robot/" file="link7_7-652eee34bbafccbee18e5c1c8f96823fcaaf242d.obj"/>
    <mesh name="r_robot/hand_0" class="r_robot/" file="hand_0-cfe318371d80d790934fba8bf6b6fb7f64071ac6.obj"/>
    <mesh name="r_robot/hand_1" class="r_robot/" file="hand_1-7cd93918f5bc964665658b0af0ff92876fe9a85d.obj"/>
    <mesh name="r_robot/hand_2" class="r_robot/" file="hand_2-9aff904f0b08a77437e7894da1d4efc4d4a52059.obj"/>
    <mesh name="r_robot/hand_3" class="r_robot/" file="hand_3-9909795ec9ec03e824cbb49691c32a4366fb2f4d.obj"/>
    <mesh name="r_robot/hand_4" class="r_robot/" file="hand_4-8a7602e34e1ed3ddacdaa10cf857f811276d4a2c.obj"/>
    <mesh name="r_robot/finger_0" class="r_robot/" file="finger_0-cf20576acd5b52daef643d398ae3b30fee1027d3.obj"/>
    <mesh name="r_robot/finger_1" class="r_robot/" file="finger_1-87276f8cb602e3141fccda3eb9b263c18fba3fe1.obj"/>
    <material name="bimanual_insertion_peg/material_0" class="bimanual_insertion_peg/" specular="0.5" shininess="0.5" rgba="1 0.43414932000000001 0.30946585999999998 1"/>
    <mesh name="bimanual_insertion_peg/bimanual_insertion_peg" class="bimanual_insertion_peg/" file="bimanual_insertion_peg-768dd8eaac9abf8245dbe26ef58dfc20a50d941a.obj"/>
    <mesh name="bimanual_insertion_peg/bimanual_insertion_peg_collision_0" class="bimanual_insertion_peg/" file="bimanual_insertion_peg_collision_0-ce0d595fc830ce8c76d938185543e73352954367.obj"/>
    <mesh name="bimanual_insertion_peg/bimanual_insertion_peg_collision_1" class="bimanual_insertion_peg/" file="bimanual_insertion_peg_collision_1-e8e9ad11f7e0e5411b45fe84b0da1dcfeca1f923.obj"/>
    <mesh name="bimanual_insertion_peg/bimanual_insertion_peg_collision_2" class="bimanual_insertion_peg/" file="bimanual_insertion_peg_collision_2-bd7050aec8dd88bcab49a628e1b5ec891356a3fd.obj"/>
    <mesh name="bimanual_insertion_peg/bimanual_insertion_peg_collision_3" class="bimanual_insertion_peg/" file="bimanual_insertion_peg_collision_3-2b64fdaa9386eb5f75c271b2fde96c2b51b2bb6d.obj"/>
    <mesh name="bimanual_insertion_peg/bimanual_insertion_peg_collision_4" class="bimanual_insertion_peg/" file="bimanual_insertion_peg_collision_4-11e45c983b474db0fea92f83ffdf497d3738b8d1.obj"/>
    <material name="bimanual_insertion_hole3/material_0" class="bimanual_insertion_hole3/" specular="0.5" shininess="0.5" rgba="0.83879899999999996 0.83879060000000005 0.83879060000000005 1"/>
    <mesh name="bimanual_insertion_hole3/bimanual_insertion_hole3" class="bimanual_insertion_hole3/" file="bimanual_insertion_hole3-692a38a24913370b485f566b8121adc8d8ffadcc.obj"/>
    <mesh name="bimanual_insertion_hole3/bimanual_insertion_hole3_collision_0" class="bimanual_insertion_hole3/" file="bimanual_insertion_hole3_collision_0-211348860c6054b711f46443fa86fa14862f5834.obj"/>
    <mesh name="bimanual_insertion_hole3/bimanual_insertion_hole3_collision_1" class="bimanual_insertion_hole3/" file="bimanual_insertion_hole3_collision_1-e6c703f5add4c04c99106d4da527c43a86de0f51.obj"/>
    <mesh name="bimanual_insertion_hole3/bimanual_insertion_hole3_collision_2" class="bimanual_insertion_hole3/" file="bimanual_insertion_hole3_collision_2-89f3a60338c1677d503a553939e2e58b4402f9bd.obj"/>
    <mesh name="bimanual_insertion_hole3/bimanual_insertion_hole3_collision_3" class="bimanual_insertion_hole3/" file="bimanual_insertion_hole3_collision_3-38ceefa40773aa5df4ae13d88ba0c5a037aa1e0f.obj"/>
    <mesh name="bimanual_insertion_hole3/bimanual_insertion_hole3_collision_4" class="bimanual_insertion_hole3/" file="bimanual_insertion_hole3_collision_4-4d3305187d64e71bea036b6227ccf899450ff457.obj"/>
    <mesh name="bimanual_insertion_hole3/bimanual_insertion_hole3_collision_5" class="bimanual_insertion_hole3/" file="bimanual_insertion_hole3_collision_5-9d9ecebf0e4279676f8a4edc67df1fa7bb4e5a56.obj"/>
    <mesh name="bimanual_insertion_hole3/bimanual_insertion_hole3_collision_6" class="bimanual_insertion_hole3/" file="bimanual_insertion_hole3_collision_6-2696c7caa3c61791ce15f1c8a65b7fc2c0371234.obj"/>
    <mesh name="bimanual_insertion_hole3/bimanual_insertion_hole3_collision_7" class="bimanual_insertion_hole3/" file="bimanual_insertion_hole3_collision_7-2f3861316feec75d866cd5ce3f5120bd6ec08e2a.obj"/>
    <mesh name="bimanual_insertion_hole3/bimanual_insertion_hole3_collision_8" class="bimanual_insertion_hole3/" file="bimanual_insertion_hole3_collision_8-7dd14d4eb0e5fd49b94c66cdf90c7ea4c1613851.obj"/>
    <mesh name="bimanual_insertion_hole3/bimanual_insertion_hole3_collision_9" class="bimanual_insertion_hole3/" file="bimanual_insertion_hole3_collision_9-0ce461c7e3134063855f58af9ce3e73aa4befd3c.obj"/>
    <mesh name="bimanual_insertion_hole3/bimanual_insertion_hole3_collision_10" class="bimanual_insertion_hole3/" file="bimanual_insertion_hole3_collision_10-566ffa1ecb9137326c491f71455a164564beeb1b.obj"/>
    <mesh name="bimanual_insertion_hole3/bimanual_insertion_hole3_collision_11" class="bimanual_insertion_hole3/" file="bimanual_insertion_hole3_collision_11-ce5cc2da2b2cb10d11f87b0b65605f3d5e32afdb.obj"/>
    <mesh name="bimanual_insertion_hole3/bimanual_insertion_hole3_collision_12" class="bimanual_insertion_hole3/" file="bimanual_insertion_hole3_collision_12-dd11bd7d0a6c2eeb05b0bc85d42eb7f1e3715092.obj"/>
    <mesh name="bimanual_insertion_hole3/bimanual_insertion_hole3_collision_13" class="bimanual_insertion_hole3/" file="bimanual_insertion_hole3_collision_13-ffce028374a9f8473624ffcd4407e533bcf0f336.obj"/>
    <mesh name="bimanual_insertion_hole3/bimanual_insertion_hole3_collision_14" class="bimanual_insertion_hole3/" file="bimanual_insertion_hole3_collision_14-712957a2d7d9f4668a9778c207dd920f910dc9d4.obj"/>
    <mesh name="bimanual_insertion_hole3/bimanual_insertion_hole3_collision_15" class="bimanual_insertion_hole3/" file="bimanual_insertion_hole3_collision_15-b11941007bdb948e33d5312923abfd60e8e1e6b9.obj"/>
    <mesh name="bimanual_insertion_hole3/bimanual_insertion_hole3_collision_16" class="bimanual_insertion_hole3/" file="bimanual_insertion_hole3_collision_16-f28daeb3defc535705e034942bade2d4a4f46f5a.obj"/>
    <mesh name="bimanual_insertion_hole3/bimanual_insertion_hole3_collision_17" class="bimanual_insertion_hole3/" file="bimanual_insertion_hole3_collision_17-8efb9934386ab2fa784705fad4e4a05865f5c4c4.obj"/>
    <mesh name="bimanual_insertion_hole3/bimanual_insertion_hole3_collision_18" class="bimanual_insertion_hole3/" file="bimanual_insertion_hole3_collision_18-4f76003f17677734c34ba28dd7457b33192001b6.obj"/>
    <mesh name="bimanual_insertion_hole3/bimanual_insertion_hole3_collision_19" class="bimanual_insertion_hole3/" file="bimanual_insertion_hole3_collision_19-e0f40ca1c28f0127fc001db22d451e392463bc2c.obj"/>
    <mesh name="bimanual_insertion_hole3/bimanual_insertion_hole3_collision_20" class="bimanual_insertion_hole3/" file="bimanual_insertion_hole3_collision_20-77e6a81b4e0e97b36c520e2a59ceb73304a8e4a4.obj"/>
    <mesh name="bimanual_insertion_hole3/bimanual_insertion_hole3_collision_21" class="bimanual_insertion_hole3/" file="bimanual_insertion_hole3_collision_21-61cbbf1ab9e3c3bec8398a84b233321f3674f62e.obj"/>
    <mesh name="bimanual_insertion_hole3/bimanual_insertion_hole3_collision_22" class="bimanual_insertion_hole3/" file="bimanual_insertion_hole3_collision_22-c6c22caf179cd049af4556d60ab0333082e72d3c.obj"/>
    <mesh name="bimanual_insertion_hole3/bimanual_insertion_hole3_collision_23" class="bimanual_insertion_hole3/" file="bimanual_insertion_hole3_collision_23-87f5a1bfcb2df3860b2578f0e70dc5236811952d.obj"/>
    <mesh name="bimanual_insertion_hole3/bimanual_insertion_hole3_collision_24" class="bimanual_insertion_hole3/" file="bimanual_insertion_hole3_collision_24-9e554f7166e3e685e0fe496325394838f6aee8b9.obj"/>
    <mesh name="bimanual_insertion_hole3/bimanual_insertion_hole3_collision_25" class="bimanual_insertion_hole3/" file="bimanual_insertion_hole3_collision_25-141c5c6148c4fa486a6491b3ccf0fe135d046d5e.obj"/>
    <mesh name="bimanual_insertion_hole3/bimanual_insertion_hole3_collision_26" class="bimanual_insertion_hole3/" file="bimanual_insertion_hole3_collision_26-75727194f80afd00df3133fe94619667b8d4a7dc.obj"/>
    <mesh name="bimanual_insertion_hole3/bimanual_insertion_hole3_collision_27" class="bimanual_insertion_hole3/" file="bimanual_insertion_hole3_collision_27-26406ce47e470d2effef399f1b208d0c41c6362a.obj"/>
    <mesh name="bimanual_insertion_hole3/bimanual_insertion_hole3_collision_28" class="bimanual_insertion_hole3/" file="bimanual_insertion_hole3_collision_28-fcd15bf3a40b6345611442f270c0e666e94292d7.obj"/>
    <mesh name="bimanual_insertion_hole3/bimanual_insertion_hole3_collision_29" class="bimanual_insertion_hole3/" file="bimanual_insertion_hole3_collision_29-862dad339d2a42ff3a6dc5a553fc26cc31c028e3.obj"/>
    <mesh name="bimanual_insertion_hole3/bimanual_insertion_hole3_collision_30" class="bimanual_insertion_hole3/" file="bimanual_insertion_hole3_collision_30-97df7239b5bfd9cba5691c38e5e33e219b2c956d.obj"/>
    <mesh name="bimanual_insertion_hole3/bimanual_insertion_hole3_collision_31" class="bimanual_insertion_hole3/" file="bimanual_insertion_hole3_collision_31-f51c4bcef7ccbc8dc75f2a7008214c7d018087ef.obj"/>
    <mesh name="bimanual_insertion_hole3/bimanual_insertion_hole3_collision_32" class="bimanual_insertion_hole3/" file="bimanual_insertion_hole3_collision_32-9d80728d7ac798e0e612181b24b8c0e456632627.obj"/>
    <mesh name="bimanual_insertion_hole3/bimanual_insertion_hole3_collision_33" class="bimanual_insertion_hole3/" file="bimanual_insertion_hole3_collision_33-80c121d89d3ffa381f9b094e8525646f10baa04b.obj"/>
    <mesh name="bimanual_insertion_hole3/bimanual_insertion_hole3_collision_34" class="bimanual_insertion_hole3/" file="bimanual_insertion_hole3_collision_34-c47d0eef542bb7b85ec0c90bbb433e3d5fb89f2b.obj"/>
    <mesh name="bimanual_insertion_hole3/bimanual_insertion_hole3_collision_35" class="bimanual_insertion_hole3/" file="bimanual_insertion_hole3_collision_35-3e4150908f117ab1ed0b697d4d164132e4c8b309.obj"/>
  </asset>
  <worldbody>
    <light name="//unnamed_light_0" class="/" directional="true" pos="0 0 1.5"/>
    <geom name="floor" class="/" type="plane" size="5 5 0.01" material="grid"/>
    <site name="l_robot_site" class="/" pos="-0.40000000000000002 -0.14999999999999999 0" quat="0.70710680000000004 0 0 0.70710680000000004"/>
    <body pos="-0.40000000000000002 -0.14999999999999999 0" quat="0.70710680000000004 0 0 0.70710680000000004" name="l_robot/">
      <light name="l_robot/top" class="l_robot/" mode="trackcom" pos="0 0 2"/>
      <body name="l_robot/link0" childclass="l_robot/panda">
        <inertial pos="-0.041017999999999999 -0.00013999999999999999 0.049973999999999998" mass="0.62976900000000002" fullinertia="0.00315 0.0038800000000000002 0.0042849999999999997 8.2903999999999996e-07 0.00014999999999999999 8.2299000000000006e-06"/>
        <geom name="l_robot//unnamed_geom_0" class="l_robot/visual" material="l_robot/off_white" mesh="l_robot/link0_0"/>
        <geom name="l_robot//unnamed_geom_1" class="l_robot/visual" material="l_robot/black" mesh="l_robot/link0_1"/>
        <geom name="l_robot//unnamed_geom_2" class="l_robot/visual" material="l_robot/off_white" mesh="l_robot/link0_2"/>
        <geom name="l_robot//unnamed_geom_3" class="l_robot/visual" material="l_robot/black" mesh="l_robot/link0_3"/>
        <geom name="l_robot//unnamed_geom_4" class="l_robot/visual" material="l_robot/off_white" mesh="l_robot/link0_4"/>
        <geom name="l_robot//unnamed_geom_5" class="l_robot/visual" material="l_robot/black" mesh="l_robot/link0_5"/>
        <geom name="l_robot//unnamed_geom_6" class="l_robot/visual" material="l_robot/white" mesh="l_robot/link0_7"/>
        <geom name="l_robot//unnamed_geom_7" class="l_robot/visual" material="l_robot/white" mesh="l_robot/link0_8"/>
        <geom name="l_robot//unnamed_geom_8" class="l_robot/visual" material="l_robot/black" mesh="l_robot/link0_9"/>
        <geom name="l_robot//unnamed_geom_9" class="l_robot/visual" material="l_robot/off_white" mesh="l_robot/link0_10"/>
        <geom name="l_robot//unnamed_geom_10" class="l_robot/visual" material="l_robot/white" mesh="l_robot/link0_11"/>
        <geom name="l_robot//unnamed_geom_11" class="l_robot/collision" mesh="l_robot/link0_c"/>
        <body name="l_robot/link1" pos="0 0 0.33300000000000002">
          <inertial pos="0.003875 0.002081 -0.047620000000000003" mass="4.9706840000000003" fullinertia="0.70337000000000005 0.70660999999999996 0.0091170000000000001 -0.00013899999999999999 0.0067720000000000002 0.019168999999999999"/>
          <joint name="l_robot/joint1"/>
          <geom name="l_robot//unnamed_geom_12" class="l_robot/visual" material="l_robot/white" mesh="l_robot/link1"/>
          <geom name="l_robot//unnamed_geom_13" class="l_robot/collision" mesh="l_robot/link1_c"/>
          <body name="l_robot/link2" quat="1 -1 0 0">
            <inertial pos="-0.0031410000000000001 -0.028719999999999999 0.0034949999999999998" mass="0.646926" fullinertia="0.0079620000000000003 0.02811 0.025995000000000001 -0.0039249999999999997 0.010253999999999999 0.00070399999999999998"/>
            <joint name="l_robot/joint2" range="-1.7627999999999999 1.7627999999999999"/>
            <geom name="l_robot//unnamed_geom_14" class="l_robot/visual" material="l_robot/white" mesh="l_robot/link2"/>
            <geom name="l_robot//unnamed_geom_15" class="l_robot/collision" mesh="l_robot/link2_c"/>
            <body name="l_robot/link3" pos="0 -0.316 0" quat="1 1 0 0">
              <joint name="l_robot/joint3"/>
              <inertial pos="0.027518000000000001 0.039252000000000002 -0.066502000000000006" mass="3.2286039999999998" fullinertia="0.037241999999999997 0.036155 0.010829999999999999 -0.0047609999999999996 -0.011396 -0.012805"/>
              <geom name="l_robot//unnamed_geom_16" class="l_robot/visual" material="l_robot/white" mesh="l_robot/link3_0"/>
              <geom name="l_robot//unnamed_geom_17" class="l_robot/visual" material="l_robot/white" mesh="l_robot/link3_1"/>
              <geom name="l_robot//unnamed_geom_18" class="l_robot/visual" material="l_robot/white" mesh="l_robot/link3_2"/>
              <geom name="l_robot//unnamed_geom_19" class="l_robot/visual" material="l_robot/black" mesh="l_robot/link3_3"/>
              <geom name="l_robot//unnamed_geom_20" class="l_robot/collision" mesh="l_robot/link3_c"/>
              <body name="l_robot/link4" pos="0.082500000000000004 0 0" quat="1 1 0 0">
                <inertial pos="-0.053170000000000002 0.104419 0.027453999999999999" mass="3.5878950000000001" fullinertia="0.025853000000000001 0.019552 0.028323000000000001 0.007796 -0.0013320000000000001 0.0086409999999999994"/>
                <joint name="l_robot/joint4" range="-3.0718000000000001 -0.069800000000000001"/>
                <geom name="l_robot//unnamed_geom_21" class="l_robot/visual" material="l_robot/white" mesh="l_robot/link4_0"/>
                <geom name="l_robot//unnamed_geom_22" class="l_robot/visual" material="l_robot/white" mesh="l_robot/link4_1"/>
                <geom name="l_robot//unnamed_geom_23" class="l_robot/visual" material="l_robot/black" mesh="l_robot/link4_2"/>
                <geom name="l_robot//unnamed_geom_24" class="l_robot/visual" material="l_robot/white" mesh="l_robot/link4_3"/>
                <geom name="l_robot//unnamed_geom_25" class="l_robot/collision" mesh="l_robot/link4_c"/>
                <body name="l_robot/link5" pos="-0.082500000000000004 0.38400000000000001 0" quat="1 -1 0 0">
                  <inertial pos="-0.011953 0.041064999999999997 -0.038436999999999999" mass="1.225946" fullinertia="0.035548999999999997 0.029474 0.0086269999999999993 -0.002117 -0.0040369999999999998 0.00022900000000000001"/>
                  <joint name="l_robot/joint5"/>
                  <geom name="l_robot//unnamed_geom_26" class="l_robot/visual" material="l_robot/black" mesh="l_robot/link5_0"/>
                  <geom name="l_robot//unnamed_geom_27" class="l_robot/visual" material="l_robot/white" mesh="l_robot/link5_1"/>
                  <geom name="l_robot//unnamed_geom_28" class="l_robot/visual" material="l_robot/white" mesh="l_robot/link5_2"/>
                  <geom name="l_robot//unnamed_geom_29" class="l_robot/collision" mesh="l_robot/link5_c0"/>
                  <geom name="l_robot//unnamed_geom_30" class="l_robot/collision" mesh="l_robot/link5_c1"/>
                  <geom name="l_robot//unnamed_geom_31" class="l_robot/collision" mesh="l_robot/link5_c2"/>
                  <body name="l_robot/link6" quat="1 1 0 0">
                    <inertial pos="0.060149000000000001 -0.014116999999999999 -0.010517" mass="1.666555" fullinertia="0.001964 0.0043540000000000002 0.0054330000000000003 0.00010900000000000001 -0.001158 0.00034099999999999999"/>
                    <joint name="l_robot/joint6" range="-0.017500000000000002 3.7524999999999999"/>
                    <geom name="l_robot//unnamed_geom_32" class="l_robot/visual" material="l_robot/off_white" mesh="l_robot/link6_0"/>
                    <geom name="l_robot//unnamed_geom_33" class="l_robot/visual" material="l_robot/white" mesh="l_robot/link6_1"/>
                    <geom name="l_robot//unnamed_geom_34" class="l_robot/visual" material="l_robot/black" mesh="l_robot/link6_2"/>
                    <geom name="l_robot//unnamed_geom_35" class="l_robot/visual" material="l_robot/white" mesh="l_robot/link6_3"/>
                    <geom name="l_robot//unnamed_geom_36" class="l_robot/visual" material="l_robot/white" mesh="l_robot/link6_4"/>
                    <geom name="l_robot//unnamed_geom_37" class="l_robot/visual" material="l_robot/white" mesh="l_robot/link6_5"/>
                    <geom name="l_robot//unnamed_geom_38" class="l_robot/visual" material="l_robot/white" mesh="l_robot/link6_6"/>
                    <geom name="l_robot//unnamed_geom_39" class="l_robot/visual" material="l_robot/light_blue" mesh="l_robot/link6_7"/>
                    <geom name="l_robot//unnamed_geom_40" class="l_robot/visual" material="l_robot/light_blue" mesh="l_robot/link6_8"/>
                    <geom name="l_robot//unnamed_geom_41" class="l_robot/visual" material="l_robot/black" mesh="l_robot/link6_9"/>
                    <geom name="l_robot//unnamed_geom_42" class="l_robot/visual" material="l_robot/black" mesh="l_robot/link6_10"/>
                    <geom name="l_robot//unnamed_geom_43" class="l_robot/visual" material="l_robot/white" mesh="l_robot/link6_11"/>
                    <geom name="l_robot//unnamed_geom_44" class="l_robot/visual" material="l_robot/green" mesh="l_robot/link6_12"/>
                    <geom name="l_robot//unnamed_geom_45" class="l_robot/visual" material="l_robot/white" mesh="l_robot/link6_13"/>
                    <geom name="l_robot//unnamed_geom_46" class="l_robot/visual" material="l_robot/black" mesh="l_robot/link6_14"/>
                    <geom name="l_robot//unnamed_geom_47" class="l_robot/visual" material="l_robot/black" mesh="l_robot/link6_15"/>
                    <geom name="l_robot//unnamed_geom_48" class="l_robot/visual" material="l_robot/white" mesh="l_robot/link6_16"/>
                    <geom name="l_robot//unnamed_geom_49" class="l_robot/collision" mesh="l_robot/link6_c"/>
                    <body name="l_robot/link7" pos="0.087999999999999995 0 0" quat="1 1 0 0">
                      <body name="l_robot/attachment" pos="0 0 0.210399" quat="0.38268340000000001 0 0 0.92387949999999996"/>
                      <inertial pos="0.010517 -0.0042519999999999997 0.061596999999999999" mass="0.73552200000000001" fullinertia="0.012515999999999999 0.010026999999999999 0.0048149999999999998 -0.000428 -0.001196 -0.00074100000000000001"/>
                      <joint name="l_robot/joint7"/>
                      <geom name="l_robot//unnamed_geom_50" class="l_robot/visual" material="l_robot/white" mesh="l_robot/link7_0"/>
                      <geom name="l_robot//unnamed_geom_51" class="l_robot/visual" material="l_robot/black" mesh="l_robot/link7_1"/>
                      <geom name="l_robot//unnamed_geom_52" class="l_robot/visual" material="l_robot/black" mesh="l_robot/link7_2"/>
                      <geom name="l_robot//unnamed_geom_53" class="l_robot/visual" material="l_robot/black" mesh="l_robot/link7_3"/>
                      <geom name="l_robot//unnamed_geom_54" class="l_robot/visual" material="l_robot/black" mesh="l_robot/link7_4"/>
                      <geom name="l_robot//unnamed_geom_55" class="l_robot/visual" material="l_robot/black" mesh="l_robot/link7_5"/>
                      <geom name="l_robot//unnamed_geom_56" class="l_robot/visual" material="l_robot/black" mesh="l_robot/link7_6"/>
                      <geom name="l_robot//unnamed_geom_57" class="l_robot/visual" material="l_robot/white" mesh="l_robot/link7_7"/>
                      <geom name="l_robot//unnamed_geom_58" class="l_robot/collision" mesh="l_robot/link7_c"/>
                      <body name="l_robot/hand" pos="0 0 0.107" quat="0.92387949999999996 0 0 -0.38268340000000001">
                        <inertial pos="-0.01 0 0.029999999999999999" mass="0.72999999999999998" diaginertia="0.001 0.0025000000000000001 0.0016999999999999999"/>
                        <geom name="l_robot//unnamed_geom_59" class="l_robot/visual" material="l_robot/off_white" mesh="l_robot/hand_0"/>
                        <geom name="l_robot//unnamed_geom_60" class="l_robot/visual" material="l_robot/black" mesh="l_robot/hand_1"/>
                        <geom name="l_robot//unnamed_geom_61" class="l_robot/visual" material="l_robot/black" mesh="l_robot/hand_2"/>
                        <geom name="l_robot//unnamed_geom_62" class="l_robot/visual" material="l_robot/white" mesh="l_robot/hand_3"/>
                        <geom name="l_robot//unnamed_geom_63" class="l_robot/visual" material="l_robot/off_white" mesh="l_robot/hand_4"/>
                        <geom name="l_robot//unnamed_geom_64" class="l_robot/collision" mesh="l_robot/hand_c"/>
                        <body name="l_robot/left_finger" pos="0 0 0.058400000000000001">
                          <inertial pos="0 0 0" mass="0.014999999999999999" diaginertia="2.3750000000000001e-06 2.3750000000000001e-06 7.5000000000000002e-07"/>
                          <joint name="l_robot/finger_joint1" class="l_robot/finger"/>
                          <geom name="l_robot//unnamed_geom_65" class="l_robot/visual" material="l_robot/off_white" mesh="l_robot/finger_0"/>
                          <geom name="l_robot//unnamed_geom_66" class="l_robot/visual" material="l_robot/black" mesh="l_robot/finger_1"/>
                          <geom name="l_robot//unnamed_geom_67" class="l_robot/collision" mesh="l_robot/finger_0"/>
                          <geom name="l_robot//unnamed_geom_68" class="l_robot/fingertip_pad_collision_1"/>
                          <body name="l_robot/left_finger_base" pos="0 0.02 0" quat="1 0 0 0"/>
                          <body name="l_robot/left_finger_tip" pos="0 0 0.050000000000000003" quat="1 0 0 0"/>
                        </body>
                        <body name="l_robot/right_finger" pos="0 0 0.058400000000000001" quat="0 0 0 1">
                          <inertial pos="0 0 0" mass="0.014999999999999999" diaginertia="2.3750000000000001e-06 2.3750000000000001e-06 7.5000000000000002e-07"/>
                          <joint name="l_robot/finger_joint2" class="l_robot/finger"/>
                          <geom name="l_robot//unnamed_geom_69" class="l_robot/visual" material="l_robot/off_white" mesh="l_robot/finger_0"/>
                          <geom name="l_robot//unnamed_geom_70" class="l_robot/visual" material="l_robot/black" mesh="l_robot/finger_1"/>
                          <geom name="l_robot//unnamed_geom_71" class="l_robot/collision" mesh="l_robot/finger_0"/>
                          <geom name="l_robot//unnamed_geom_72" class="l_robot/fingertip_pad_collision_1"/>
                          <body name="l_robot/right_finger_base" pos="0 0.02 0" quat="1 0 0 0"/>
                          <body name="l_robot/right_finger_tip" pos="0 0 0.050000000000000003" quat="1 0 0 0"/>
                        </body>
                      </body>
                    </body>
                  </body>
                </body>
              </body>
            </body>
          </body>
        </body>
      </body>
    </body>
    <site name="r_robot_site" class="/" pos="0.40000000000000002 -0.14999999999999999 0" quat="0.70710680000000004 0 0 0.70710680000000004"/>
    <body pos="0.40000000000000002 -0.14999999999999999 0" quat="0.70710680000000004 0 0 0.70710680000000004" name="r_robot/">
      <light name="r_robot/top" class="r_robot/" mode="trackcom" pos="0 0 2"/>
      <body name="r_robot/link0" childclass="r_robot/panda">
        <inertial pos="-0.041017999999999999 -0.00013999999999999999 0.049973999999999998" mass="0.62976900000000002" fullinertia="0.00315 0.0038800000000000002 0.0042849999999999997 8.2903999999999996e-07 0.00014999999999999999 8.2299000000000006e-06"/>
        <geom name="r_robot//unnamed_geom_0" class="r_robot/visual" material="r_robot/off_white" mesh="r_robot/link0_0"/>
        <geom name="r_robot//unnamed_geom_1" class="r_robot/visual" material="r_robot/black" mesh="r_robot/link0_1"/>
        <geom name="r_robot//unnamed_geom_2" class="r_robot/visual" material="r_robot/off_white" mesh="r_robot/link0_2"/>
        <geom name="r_robot//unnamed_geom_3" class="r_robot/visual" material="r_robot/black" mesh="r_robot/link0_3"/>
        <geom name="r_robot//unnamed_geom_4" class="r_robot/visual" material="r_robot/off_white" mesh="r_robot/link0_4"/>
        <geom name="r_robot//unnamed_geom_5" class="r_robot/visual" material="r_robot/black" mesh="r_robot/link0_5"/>
        <geom name="r_robot//unnamed_geom_6" class="r_robot/visual" material="r_robot/white" mesh="r_robot/link0_7"/>
        <geom name="r_robot//unnamed_geom_7" class="r_robot/visual" material="r_robot/white" mesh="r_robot/link0_8"/>
        <geom name="r_robot//unnamed_geom_8" class="r_robot/visual" material="r_robot/black" mesh="r_robot/link0_9"/>
        <geom name="r_robot//unnamed_geom_9" class="r_robot/visual" material="r_robot/off_white" mesh="r_robot/link0_10"/>
        <geom name="r_robot//unnamed_geom_10" class="r_robot/visual" material="r_robot/white" mesh="r_robot/link0_11"/>
        <geom name="r_robot//unnamed_geom_11" class="r_robot/collision" mesh="r_robot/link0_c"/>
        <body name="r_robot/link1" pos="0 0 0.33300000000000002">
          <inertial pos="0.003875 0.002081 -0.047620000000000003" mass="4.9706840000000003" fullinertia="0.70337000000000005 0.70660999999999996 0.0091170000000000001 -0.00013899999999999999 0.0067720000000000002 0.019168999999999999"/>
          <joint name="r_robot/joint1"/>
          <geom name="r_robot//unnamed_geom_12" class="r_robot/visual" material="r_robot/white" mesh="r_robot/link1"/>
          <geom name="r_robot//unnamed_geom_13" class="r_robot/collision" mesh="r_robot/link1_c"/>
          <body name="r_robot/link2" quat="1 -1 0 0">
            <inertial pos="-0.0031410000000000001 -0.028719999999999999 0.0034949999999999998" mass="0.646926" fullinertia="0.0079620000000000003 0.02811 0.025995000000000001 -0.0039249999999999997 0.010253999999999999 0.00070399999999999998"/>
            <joint name="r_robot/joint2" range="-1.7627999999999999 1.7627999999999999"/>
            <geom name="r_robot//unnamed_geom_14" class="r_robot/visual" material="r_robot/white" mesh="r_robot/link2"/>
            <geom name="r_robot//unnamed_geom_15" class="r_robot/collision" mesh="r_robot/link2_c"/>
            <body name="r_robot/link3" pos="0 -0.316 0" quat="1 1 0 0">
              <joint name="r_robot/joint3"/>
              <inertial pos="0.027518000000000001 0.039252000000000002 -0.066502000000000006" mass="3.2286039999999998" fullinertia="0.037241999999999997 0.036155 0.010829999999999999 -0.0047609999999999996 -0.011396 -0.012805"/>
              <geom name="r_robot//unnamed_geom_16" class="r_robot/visual" material="r_robot/white" mesh="r_robot/link3_0"/>
              <geom name="r_robot//unnamed_geom_17" class="r_robot/visual" material="r_robot/white" mesh="r_robot/link3_1"/>
              <geom name="r_robot//unnamed_geom_18" class="r_robot/visual" material="r_robot/white" mesh="r_robot/link3_2"/>
              <geom name="r_robot//unnamed_geom_19" class="r_robot/visual" material="r_robot/black" mesh="r_robot/link3_3"/>
              <geom name="r_robot//unnamed_geom_20" class="r_robot/collision" mesh="r_robot/link3_c"/>
              <body name="r_robot/link4" pos="0.082500000000000004 0 0" quat="1 1 0 0">
                <inertial pos="-0.053170000000000002 0.104419 0.027453999999999999" mass="3.5878950000000001" fullinertia="0.025853000000000001 0.019552 0.028323000000000001 0.007796 -0.0013320000000000001 0.0086409999999999994"/>
                <joint name="r_robot/joint4" range="-3.0718000000000001 -0.069800000000000001"/>
                <geom name="r_robot//unnamed_geom_21" class="r_robot/visual" material="r_robot/white" mesh="r_robot/link4_0"/>
                <geom name="r_robot//unnamed_geom_22" class="r_robot/visual" material="r_robot/white" mesh="r_robot/link4_1"/>
                <geom name="r_robot//unnamed_geom_23" class="r_robot/visual" material="r_robot/black" mesh="r_robot/link4_2"/>
                <geom name="r_robot//unnamed_geom_24" class="r_robot/visual" material="r_robot/white" mesh="r_robot/link4_3"/>
                <geom name="r_robot//unnamed_geom_25" class="r_robot/collision" mesh="r_robot/link4_c"/>
                <body name="r_robot/link5" pos="-0.082500000000000004 0.38400000000000001 0" quat="1 -1 0 0">
                  <inertial pos="-0.011953 0.041064999999999997 -0.038436999999999999" mass="1.225946" fullinertia="0.035548999999999997 0.029474 0.0086269999999999993 -0.002117 -0.0040369999999999998 0.00022900000000000001"/>
                  <joint name="r_robot/joint5"/>
                  <geom name="r_robot//unnamed_geom_26" class="r_robot/visual" material="r_robot/black" mesh="r_robot/link5_0"/>
                  <geom name="r_robot//unnamed_geom_27" class="r_robot/visual" material="r_robot/white" mesh="r_robot/link5_1"/>
                  <geom name="r_robot//unnamed_geom_28" class="r_robot/visual" material="r_robot/white" mesh="r_robot/link5_2"/>
                  <geom name="r_robot//unnamed_geom_29" class="r_robot/collision" mesh="r_robot/link5_c0"/>
                  <geom name="r_robot//unnamed_geom_30" class="r_robot/collision" mesh="r_robot/link5_c1"/>
                  <geom name="r_robot//unnamed_geom_31" class="r_robot/collision" mesh="r_robot/link5_c2"/>
                  <body name="r_robot/link6" quat="1 1 0 0">
                    <inertial pos="0.060149000000000001 -0.014116999999999999 -0.010517" mass="1.666555" fullinertia="0.001964 0.0043540000000000002 0.0054330000000000003 0.00010900000000000001 -0.001158 0.00034099999999999999"/>
                    <joint name="r_robot/joint6" range="-0.017500000000000002 3.7524999999999999"/>
                    <geom name="r_robot//unnamed_geom_32" class="r_robot/visual" material="r_robot/off_white" mesh="r_robot/link6_0"/>
                    <geom name="r_robot//unnamed_geom_33" class="r_robot/visual" material="r_robot/white" mesh="r_robot/link6_1"/>
                    <geom name="r_robot//unnamed_geom_34" class="r_robot/visual" material="r_robot/black" mesh="r_robot/link6_2"/>
                    <geom name="r_robot//unnamed_geom_35" class="r_robot/visual" material="r_robot/white" mesh="r_robot/link6_3"/>
                    <geom name="r_robot//unnamed_geom_36" class="r_robot/visual" material="r_robot/white" mesh="r_robot/link6_4"/>
                    <geom name="r_robot//unnamed_geom_37" class="r_robot/visual" material="r_robot/white" mesh="r_robot/link6_5"/>
                    <geom name="r_robot//unnamed_geom_38" class="r_robot/visual" material="r_robot/white" mesh="r_robot/link6_6"/>
                    <geom name="r_robot//unnamed_geom_39" class="r_robot/visual" material="r_robot/light_blue" mesh="r_robot/link6_7"/>
                    <geom name="r_robot//unnamed_geom_40" class="r_robot/visual" material="r_robot/light_blue" mesh="r_robot/link6_8"/>
                    <geom name="r_robot//unnamed_geom_41" class="r_robot/visual" material="r_robot/black" mesh="r_robot/link6_9"/>
                    <geom name="r_robot//unnamed_geom_42" class="r_robot/visual" material="r_robot/black" mesh="r_robot/link6_10"/>
                    <geom name="r_robot//unnamed_geom_43" class="r_robot/visual" material="r_robot/white" mesh="r_robot/link6_11"/>
                    <geom name="r_robot//unnamed_geom_44" class="r_robot/visual" material="r_robot/green" mesh="r_robot/link6_12"/>
                    <geom name="r_robot//unnamed_geom_45" class="r_robot/visual" material="r_robot/white" mesh="r_robot/link6_13"/>
                    <geom name="r_robot//unnamed_geom_46" class="r_robot/visual" material="r_robot/black" mesh="r_robot/link6_14"/>
                    <geom name="r_robot//unnamed_geom_47" class="r_robot/visual" material="r_robot/black" mesh="r_robot/link6_15"/>
                    <geom name="r_robot//unnamed_geom_48" class="r_robot/visual" material="r_robot/white" mesh="r_robot/link6_16"/>
                    <geom name="r_robot//unnamed_geom_49" class="r_robot/collision" mesh="r_robot/link6_c"/>
                    <body name="r_robot/link7" pos="0.087999999999999995 0 0" quat="1 1 0 0">
                      <body name="r_robot/attachment" pos="0 0 0.210399" quat="0.38268340000000001 0 0 0.92387949999999996"/>
                      <inertial pos="0.010517 -0.0042519999999999997 0.061596999999999999" mass="0.73552200000000001" fullinertia="0.012515999999999999 0.010026999999999999 0.0048149999999999998 -0.000428 -0.001196 -0.00074100000000000001"/>
                      <joint name="r_robot/joint7"/>
                      <geom name="r_robot//unnamed_geom_50" class="r_robot/visual" material="r_robot/white" mesh="r_robot/link7_0"/>
                      <geom name="r_robot//unnamed_geom_51" class="r_robot/visual" material="r_robot/black" mesh="r_robot/link7_1"/>
                      <geom name="r_robot//unnamed_geom_52" class="r_robot/visual" material="r_robot/black" mesh="r_robot/link7_2"/>
                      <geom name="r_robot//unnamed_geom_53" class="r_robot/visual" material="r_robot/black" mesh="r_robot/link7_3"/>
                      <geom name="r_robot//unnamed_geom_54" class="r_robot/visual" material="r_robot/black" mesh="r_robot/link7_4"/>
                      <geom name="r_robot//unnamed_geom_55" class="r_robot/visual" material="r_robot/black" mesh="r_robot/link7_5"/>
                      <geom name="r_robot//unnamed_geom_56" class="r_robot/visual" material="r_robot/black" mesh="r_robot/link7_6"/>
                      <geom name="r_robot//unnamed_geom_57" class="r_robot/visual" material="r_robot/white" mesh="r_robot/link7_7"/>
                      <geom name="r_robot//unnamed_geom_58" class="r_robot/collision" mesh="r_robot/link7_c"/>
                      <body name="r_robot/hand" pos="0 0 0.107" quat="0.92387949999999996 0 0 -0.38268340000000001">
                        <inertial pos="-0.01 0 0.029999999999999999" mass="0.72999999999999998" diaginertia="0.001 0.0025000000000000001 0.0016999999999999999"/>
                        <geom name="r_robot//unnamed_geom_59" class="r_robot/visual" material="r_robot/off_white" mesh="r_robot/hand_0"/>
                        <geom name="r_robot//unnamed_geom_60" class="r_robot/visual" material="r_robot/black" mesh="r_robot/hand_1"/>
                        <geom name="r_robot//unnamed_geom_61" class="r_robot/visual" material="r_robot/black" mesh="r_robot/hand_2"/>
                        <geom name="r_robot//unnamed_geom_62" class="r_robot/visual" material="r_robot/white" mesh="r_robot/hand_3"/>
                        <geom name="r_robot//unnamed_geom_63" class="r_robot/visual" material="r_robot/off_white" mesh="r_robot/hand_4"/>
                        <geom name="r_robot//unnamed_geom_64" class="r_robot/collision" mesh="r_robot/hand_c"/>
                        <body name="r_robot/left_finger" pos="0 0 0.058400000000000001">
                          <inertial pos="0 0 0" mass="0.014999999999999999" diaginertia="2.3750000000000001e-06 2.3750000000000001e-06 7.5000000000000002e-07"/>
                          <joint name="r_robot/finger_joint1" class="r_robot/finger"/>
                          <geom name="r_robot//unnamed_geom_65" class="r_robot/visual" material="r_robot/off_white" mesh="r_robot/finger_0"/>
                          <geom name="r_robot//unnamed_geom_66" class="r_robot/visual" material="r_robot/black" mesh="r_robot/finger_1"/>
                          <geom name="r_robot//unnamed_geom_67" class="r_robot/collision" mesh="r_robot/finger_0"/>
                          <geom name="r_robot//unnamed_geom_68" class="r_robot/fingertip_pad_collision_1"/>
                          <body name="r_robot/left_finger_base" pos="0 0.02 0" quat="1 0 0 0"/>
                          <body name="r_robot/left_finger_tip" pos="0 0 0.050000000000000003" quat="1 0 0 0"/>
                        </body>
                        <body name="r_robot/right_finger" pos="0 0 0.058400000000000001" quat="0 0 0 1">
                          <inertial pos="0 0 0" mass="0.014999999999999999" diaginertia="2.3750000000000001e-06 2.3750000000000001e-06 7.5000000000000002e-07"/>
                          <joint name="r_robot/finger_joint2" class="r_robot/finger"/>
                          <geom name="r_robot//unnamed_geom_69" class="r_robot/visual" material="r_robot/off_white" mesh="r_robot/finger_0"/>
                          <geom name="r_robot//unnamed_geom_70" class="r_robot/visual" material="r_robot/black" mesh="r_robot/finger_1"/>
                          <geom name="r_robot//unnamed_geom_71" class="r_robot/collision" mesh="r_robot/finger_0"/>
                          <geom name="r_robot//unnamed_geom_72" class="r_robot/fingertip_pad_collision_1"/>
                          <body name="r_robot/right_finger_base" pos="0 0.02 0" quat="1 0 0 0"/>
                          <body name="r_robot/right_finger_tip" pos="0 0 0.050000000000000003" quat="1 0 0 0"/>
                        </body>
                      </body>
                    </body>
                  </body>
                </body>
              </body>
            </body>
          </body>
        </body>
      </body>
    </body>
    <body name="left_lb_target" mocap="true">
      <geom name="//unnamed_geom_1" class="/" type="box" contype="0" conaffinity="0" group="4" size="0.01 0.01 0.01" rgba="0.29999999999999999 0.59999999999999998 0.29999999999999999 0.90000000000000002"/>
      <geom name="//unnamed_geom_2" class="/" type="box" contype="0" conaffinity="0" group="4" size="0.01 0.002 0.002" rgba="1 0 0 1" pos="0.01 0 0"/>
      <geom name="//unnamed_geom_3" class="/" type="box" contype="0" conaffinity="0" group="4" size="0.002 0.01 0.002" rgba="0 1 0 1" pos="0 0.01 0"/>
      <geom name="//unnamed_geom_4" class="/" type="box" contype="0" conaffinity="0" group="4" size="0.002 0.002 0.01" rgba="0 0 1 1" pos="0 0 0.01"/>
    </body>
    <body name="left_lf_target" mocap="true">
      <geom name="//unnamed_geom_5" class="/" type="box" contype="0" conaffinity="0" group="4" size="0.01 0.01 0.01" rgba="0.29999999999999999 0.59999999999999998 0.29999999999999999 0.90000000000000002"/>
      <geom name="//unnamed_geom_6" class="/" type="box" contype="0" conaffinity="0" group="4" size="0.01 0.002 0.002" rgba="1 0 0 1" pos="0.01 0 0"/>
      <geom name="//unnamed_geom_7" class="/" type="box" contype="0" conaffinity="0" group="4" size="0.002 0.01 0.002" rgba="0 1 0 1" pos="0 0.01 0"/>
      <geom name="//unnamed_geom_8" class="/" type="box" contype="0" conaffinity="0" group="4" size="0.002 0.002 0.01" rgba="0 0 1 1" pos="0 0 0.01"/>
    </body>
    <body name="left_rb_target" mocap="true">
      <geom name="//unnamed_geom_9" class="/" type="box" contype="0" conaffinity="0" group="4" size="0.01 0.01 0.01" rgba="0.29999999999999999 0.59999999999999998 0.29999999999999999 0.90000000000000002"/>
      <geom name="//unnamed_geom_10" class="/" type="box" contype="0" conaffinity="0" group="4" size="0.01 0.002 0.002" rgba="1 0 0 1" pos="0.01 0 0"/>
      <geom name="//unnamed_geom_11" class="/" type="box" contype="0" conaffinity="0" group="4" size="0.002 0.01 0.002" rgba="0 1 0 1" pos="0 0.01 0"/>
      <geom name="//unnamed_geom_12" class="/" type="box" contype="0" conaffinity="0" group="4" size="0.002 0.002 0.01" rgba="0 0 1 1" pos="0 0 0.01"/>
    </body>
    <body name="left_rf_target" mocap="true">
      <geom name="//unnamed_geom_13" class="/" type="box" contype="0" conaffinity="0" group="4" size="0.01 0.01 0.01" rgba="0.29999999999999999 0.59999999999999998 0.29999999999999999 0.90000000000000002"/>
      <geom name="//unnamed_geom_14" class="/" type="box" contype="0" conaffinity="0" group="4" size="0.01 0.002 0.002" rgba="1 0 0 1" pos="0.01 0 0"/>
      <geom name="//unnamed_geom_15" class="/" type="box" contype="0" conaffinity="0" group="4" size="0.002 0.01 0.002" rgba="0 1 0 1" pos="0 0.01 0"/>
      <geom name="//unnamed_geom_16" class="/" type="box" contype="0" conaffinity="0" group="4" size="0.002 0.002 0.01" rgba="0 0 1 1" pos="0 0 0.01"/>
    </body>
    <body name="right_lb_target" mocap="true">
      <geom name="//unnamed_geom_17" class="/" type="box" contype="0" conaffinity="0" group="4" size="0.01 0.01 0.01" rgba="0.29999999999999999 0.59999999999999998 0.29999999999999999 0.90000000000000002"/>
      <geom name="//unnamed_geom_18" class="/" type="box" contype="0" conaffinity="0" group="4" size="0.01 0.002 0.002" rgba="1 0 0 1" pos="0.01 0 0"/>
      <geom name="//unnamed_geom_19" class="/" type="box" contype="0" conaffinity="0" group="4" size="0.002 0.01 0.002" rgba="0 1 0 1" pos="0 0.01 0"/>
      <geom name="//unnamed_geom_20" class="/" type="box" contype="0" conaffinity="0" group="4" size="0.002 0.002 0.01" rgba="0 0 1 1" pos="0 0 0.01"/>
    </body>
    <body name="right_lf_target" mocap="true">
      <geom name="//unnamed_geom_21" class="/" type="box" contype="0" conaffinity="0" group="4" size="0.01 0.01 0.01" rgba="0.29999999999999999 0.59999999999999998 0.29999999999999999 0.90000000000000002"/>
      <geom name="//unnamed_geom_22" class="/" type="box" contype="0" conaffinity="0" group="4" size="0.01 0.002 0.002" rgba="1 0 0 1" pos="0.01 0 0"/>
      <geom name="//unnamed_geom_23" class="/" type="box" contype="0" conaffinity="0" group="4" size="0.002 0.01 0.002" rgba="0 1 0 1" pos="0 0.01 0"/>
      <geom name="//unnamed_geom_24" class="/" type="box" contype="0" conaffinity="0" group="4" size="0.002 0.002 0.01" rgba="0 0 1 1" pos="0 0 0.01"/>
    </body>
    <body name="right_rb_target" mocap="true">
      <geom name="//unnamed_geom_25" class="/" type="box" contype="0" conaffinity="0" group="4" size="0.01 0.01 0.01" rgba="0.29999999999999999 0.59999999999999998 0.29999999999999999 0.90000000000000002"/>
      <geom name="//unnamed_geom_26" class="/" type="box" contype="0" conaffinity="0" group="4" size="0.01 0.002 0.002" rgba="1 0 0 1" pos="0.01 0 0"/>
      <geom name="//unnamed_geom_27" class="/" type="box" contype="0" conaffinity="0" group="4" size="0.002 0.01 0.002" rgba="0 1 0 1" pos="0 0.01 0"/>
      <geom name="//unnamed_geom_28" class="/" type="box" contype="0" conaffinity="0" group="4" size="0.002 0.002 0.01" rgba="0 0 1 1" pos="0 0 0.01"/>
    </body>
    <body name="right_rf_target" mocap="true">
      <geom name="//unnamed_geom_29" class="/" type="box" contype="0" conaffinity="0" group="4" size="0.01 0.01 0.01" rgba="0.29999999999999999 0.59999999999999998 0.29999999999999999 0.90000000000000002"/>
      <geom name="//unnamed_geom_30" class="/" type="box" contype="0" conaffinity="0" group="4" size="0.01 0.002 0.002" rgba="1 0 0 1" pos="0.01 0 0"/>
      <geom name="//unnamed_geom_31" class="/" type="box" contype="0" conaffinity="0" group="4" size="0.002 0.01 0.002" rgba="0 1 0 1" pos="0 0.01 0"/>
      <geom name="//unnamed_geom_32" class="/" type="box" contype="0" conaffinity="0" group="4" size="0.002 0.002 0.01" rgba="0 0 1 1" pos="0 0 0.01"/>
    </body>
    <body name="bimanual_insertion_peg/">
      <freejoint name="bimanual_insertion_peg/"/>
      <body name="bimanual_insertion_peg/bimanual_insertion_peg">
        <geom name="bimanual_insertion_peg//unnamed_geom_0" class="bimanual_insertion_peg/visual" material="bimanual_insertion_peg/material_0" mesh="bimanual_insertion_peg/bimanual_insertion_peg"/>
        <geom name="bimanual_insertion_peg//unnamed_geom_1" class="bimanual_insertion_peg/collision" rgba="0.062104185020795177 0.44113599959532435 0.41770906890680159 1" mesh="bimanual_insertion_peg/bimanual_insertion_peg_collision_0"/>
        <geom name="bimanual_insertion_peg//unnamed_geom_2" class="bimanual_insertion_peg/collision" rgba="0.17681727249478063 0.14267285382542783 0.6285171701775597 1" mesh="bimanual_insertion_peg/bimanual_insertion_peg_collision_1"/>
        <geom name="bimanual_insertion_peg//unnamed_geom_3" class="bimanual_insertion_peg/collision" rgba="0.050112265035650694 0.65888430189799507 0.90744918986112566 1" mesh="bimanual_insertion_peg/bimanual_insertion_peg_collision_2"/>
        <geom name="bimanual_insertion_peg//unnamed_geom_4" class="bimanual_insertion_peg/collision" rgba="0.79506577295215664 0.97467647594740325 0.29401471677047364 1" mesh="bimanual_insertion_peg/bimanual_insertion_peg_collision_3"/>
        <geom name="bimanual_insertion_peg//unnamed_geom_5" class="bimanual_insertion_peg/collision" rgba="0.2831358113568071 0.6284208037284349 0.27884504288434597 1" mesh="bimanual_insertion_peg/bimanual_insertion_peg_collision_4"/>
        <body name="bimanual_insertion_peg/bimanual_insertion_peg_axis" pos="0 0 0">
          <geom name="bimanual_insertion_peg//unnamed_geom_6" class="bimanual_insertion_peg/" type="box" contype="0" conaffinity="0" group="5" size="0.029999999999999999 0.029999999999999999 0.029999999999999999" rgba="0.59999999999999998 0.29999999999999999 0.29999999999999999 0.5"/>
          <geom name="bimanual_insertion_peg//unnamed_geom_7" class="bimanual_insertion_peg/" type="box" contype="0" conaffinity="0" group="5" size="0.059999999999999998 0.002 0.002" rgba="1 0 0 0.5" pos="0.059999999999999998 0 0"/>
          <geom name="bimanual_insertion_peg//unnamed_geom_8" class="bimanual_insertion_peg/" type="box" contype="0" conaffinity="0" group="5" size="0.002 0.059999999999999998 0.002" rgba="0 1 0 0.5" pos="0 0.059999999999999998 0"/>
          <geom name="bimanual_insertion_peg//unnamed_geom_9" class="bimanual_insertion_peg/" type="box" contype="0" conaffinity="0" group="5" size="0.002 0.002 0.059999999999999998" rgba="0 0 1 0.5" pos="0 0 0.059999999999999998"/>
        </body>
      </body>
    </body>
    <body name="bimanual_insertion_hole3/">
      <freejoint name="bimanual_insertion_hole3/"/>
      <body name="bimanual_insertion_hole3/bimanual_insertion_hole3">
        <geom name="bimanual_insertion_hole3//unnamed_geom_0" class="bimanual_insertion_hole3/visual" material="bimanual_insertion_hole3/material_0" mesh="bimanual_insertion_hole3/bimanual_insertion_hole3"/>
        <geom name="bimanual_insertion_hole3//unnamed_geom_1" class="bimanual_insertion_hole3/collision" rgba="0.30221038034455772 0.32761729608583168 0.084550713099481145 1" mesh="bimanual_insertion_hole3/bimanual_insertion_hole3_collision_0"/>
        <geom name="bimanual_insertion_hole3//unnamed_geom_2" class="bimanual_insertion_hole3/collision" rgba="0.0021379198056391546 0.018698668908963767 0.037717902352499721 1" mesh="bimanual_insertion_hole3/bimanual_insertion_hole3_collision_1"/>
        <geom name="bimanual_insertion_hole3//unnamed_geom_3" class="bimanual_insertion_hole3/collision" rgba="0.95800700595583022 0.048811678882452747 0.57485821379532664 1" mesh="bimanual_insertion_hole3/bimanual_insertion_hole3_collision_2"/>
        <geom name="bimanual_insertion_hole3//unnamed_geom_4" class="bimanual_insertion_hole3/collision" rgba="0.92333436128470092 0.21079536017266309 0.6574924391853213 1" mesh="bimanual_insertion_hole3/bimanual_insertion_hole3_collision_3"/>
        <geom name="bimanual_insertion_hole3//unnamed_geom_5" class="bimanual_insertion_hole3/collision" rgba="0.70374255556010157 0.16054225330151206 0.29737568292543703 1" mesh="bimanual_insertion_hole3/bimanual_insertion_hole3_collision_4"/>
        <geom name="bimanual_insertion_hole3//unnamed_geom_6" class="bimanual_insertion_hole3/collision" rgba="0.039339014807803996 0.49970709327067309 0.82593568861477229 1" mesh="bimanual_insertion_hole3/bimanual_insertion_hole3_collision_5"/>
        <geom name="bimanual_insertion_hole3//unnamed_geom_7" class="bimanual_insertion_hole3/collision" rgba="0.89212026783071496 0.77464512580730249 0.42295991722648607 1" mesh="bimanual_insertion_hole3/bimanual_insertion_hole3_collision_6"/>
        <geom name="bimanual_insertion_hole3//unnamed_geom_8" class="bimanual_insertion_hole3/collision" rgba="0.05211298539870679 0.60047178627109943 0.56578491758519811 1" mesh="bimanual_insertion_hole3/bimanual_insertion_hole3_collision_7"/>
        <geom name="bimanual_insertion_hole3//unnamed_geom_9" class="bimanual_insertion_hole3/collision" rgba="0.98948133405119765 0.67960314312853387 0.43788534969257475 1" mesh="bimanual_insertion_hole3/bimanual_insertion_hole3_collision_8"/>
        <geom name="bimanual_insertion_hole3//unnamed_geom_10" class="bimanual_insertion_hole3/collision" rgba="0.56704433872091375 0.98822485701767659 0.94162933049393527 1" mesh="bimanual_insertion_hole3/bimanual_insertion_hole3_collision_9"/>
        <geom name="bimanual_insertion_hole3//unnamed_geom_11" class="bimanual_insertion_hole3/collision" rgba="0.36233821276216094 0.46403276327174281 0.70976474645769783 1" mesh="bimanual_insertion_hole3/bimanual_insertion_hole3_collision_10"/>
        <geom name="bimanual_insertion_hole3//unnamed_geom_12" class="bimanual_insertion_hole3/collision" rgba="0.36971871149316604 0.92952719347870227 0.80309933025825542 1" mesh="bimanual_insertion_hole3/bimanual_insertion_hole3_collision_11"/>
        <geom name="bimanual_insertion_hole3//unnamed_geom_13" class="bimanual_insertion_hole3/collision" rgba="0.31211088515555507 0.72106241380555558 0.70011377565948263 1" mesh="bimanual_insertion_hole3/bimanual_insertion_hole3_collision_12"/>
        <geom name="bimanual_insertion_hole3//unnamed_geom_14" class="bimanual_insertion_hole3/collision" rgba="0.52749824315237237 0.21837407022808908 0.58431395049564538 1" mesh="bimanual_insertion_hole3/bimanual_insertion_hole3_collision_13"/>
        <geom name="bimanual_insertion_hole3//unnamed_geom_15" class="bimanual_insertion_hole3/collision" rgba="0.42479647688837419 0.33447949637339491 0.13386507884128229 1" mesh="bimanual_insertion_hole3/bimanual_insertion_hole3_collision_14"/>
        <geom name="bimanual_insertion_hole3//unnamed_geom_16" class="bimanual_insertion_hole3/collision" rgba="0.53703925315954937 0.076488176775038386 0.60865571769499194 1" mesh="bimanual_insertion_hole3/bimanual_insertion_hole3_collision_15"/>
        <geom name="bimanual_insertion_hole3//unnamed_geom_17" class="bimanual_insertion_hole3/collision" rgba="0.34541530367904194 0.22125414947604927 0.28465155067685766 1" mesh="bimanual_insertion_hole3/bimanual_insertion_hole3_collision_16"/>
        <geom name="bimanual_insertion_hole3//unnamed_geom_18" class="bimanual_insertion_hole3/collision" rgba="0.18931447562198034 0.32360521303998535 0.64243414983154157 1" mesh="bimanual_insertion_hole3/bimanual_insertion_hole3_collision_17"/>
        <geom name="bimanual_insertion_hole3//unnamed_geom_19" class="bimanual_insertion_hole3/collision" rgba="0.27360333425512262 0.69167700685542211 0.41545778693077462 1" mesh="bimanual_insertion_hole3/bimanual_insertion_hole3_collision_18"/>
        <geom name="bimanual_insertion_hole3//unnamed_geom_20" class="bimanual_insertion_hole3/collision" rgba="0.86933700895845978 0.34189737379682228 0.74376084835959433 1" mesh="bimanual_insertion_hole3/bimanual_insertion_hole3_collision_19"/>
        <geom name="bimanual_insertion_hole3//unnamed_geom_21" class="bimanual_insertion_hole3/collision" rgba="0.029073799253512056 0.14553298590907326 0.49336865061814417 1" mesh="bimanual_insertion_hole3/bimanual_insertion_hole3_collision_20"/>
        <geom name="bimanual_insertion_hole3//unnamed_geom_22" class="bimanual_insertion_hole3/collision" rgba="0.30947147823950094 0.59722011953919463 0.87726526361979618 1" mesh="bimanual_insertion_hole3/bimanual_insertion_hole3_collision_21"/>
        <geom name="bimanual_insertion_hole3//unnamed_geom_23" class="bimanual_insertion_hole3/collision" rgba="0.33436498713614204 0.80070466293006293 0.87587228131224193 1" mesh="bimanual_insertion_hole3/bimanual_insertion_hole3_collision_22"/>
        <geom name="bimanual_insertion_hole3//unnamed_geom_24" class="bimanual_insertion_hole3/collision" rgba="0.3771342745622881 0.63545970131069696 0.93375664132131708 1" mesh="bimanual_insertion_hole3/bimanual_insertion_hole3_collision_23"/>
        <geom name="bimanual_insertion_hole3//unnamed_geom_25" class="bimanual_insertion_hole3/collision" rgba="0.35910100921403232 0.85262755918315924 0.74552236238918324 1" mesh="bimanual_insertion_hole3/bimanual_insertion_hole3_collision_24"/>
        <geom name="bimanual_insertion_hole3//unnamed_geom_26" class="bimanual_insertion_hole3/collision" rgba="0.79374074342837997 0.67861314895141922 0.31699642873762213 1" mesh="bimanual_insertion_hole3/bimanual_insertion_hole3_collision_25"/>
        <geom name="bimanual_insertion_hole3//unnamed_geom_27" class="bimanual_insertion_hole3/collision" rgba="0.12187045247478134 0.50816079724162933 0.91559727065570939 1" mesh="bimanual_insertion_hole3/bimanual_insertion_hole3_collision_26"/>
        <geom name="bimanual_insertion_hole3//unnamed_geom_28" class="bimanual_insertion_hole3/collision" rgba="0.23279013768984691 0.44767402403488554 0.84008584785215257 1" mesh="bimanual_insertion_hole3/bimanual_insertion_hole3_collision_27"/>
        <geom name="bimanual_insertion_hole3//unnamed_geom_29" class="bimanual_insertion_hole3/collision" rgba="0.10341556985106837 0.24697417544075007 0.31199174971984533 1" mesh="bimanual_insertion_hole3/bimanual_insertion_hole3_collision_28"/>
        <geom name="bimanual_insertion_hole3//unnamed_geom_30" class="bimanual_insertion_hole3/collision" rgba="0.78902578582136151 0.072532573102476627 0.38757022432432975 1" mesh="bimanual_insertion_hole3/bimanual_insertion_hole3_collision_29"/>
        <geom name="bimanual_insertion_hole3//unnamed_geom_31" class="bimanual_insertion_hole3/collision" rgba="0.27088831000742486 0.91443775423634388 0.87665773109444445 1" mesh="bimanual_insertion_hole3/bimanual_insertion_hole3_collision_30"/>
        <geom name="bimanual_insertion_hole3//unnamed_geom_32" class="bimanual_insertion_hole3/collision" rgba="0.90746563027158589 0.4636989804006203 0.4626906077508911 1" mesh="bimanual_insertion_hole3/bimanual_insertion_hole3_collision_31"/>
        <geom name="bimanual_insertion_hole3//unnamed_geom_33" class="bimanual_insertion_hole3/collision" rgba="0.99641447795318083 0.2351031662881008 0.84658471073020725 1" mesh="bimanual_insertion_hole3/bimanual_insertion_hole3_collision_32"/>
        <geom name="bimanual_insertion_hole3//unnamed_geom_34" class="bimanual_insertion_hole3/collision" rgba="0.1985119958829421 0.89710878073423372 0.46630798957383757 1" mesh="bimanual_insertion_hole3/bimanual_insertion_hole3_collision_33"/>
        <geom name="bimanual_insertion_hole3//unnamed_geom_35" class="bimanual_insertion_hole3/collision" rgba="0.37256158165121556 0.59992019979442013 0.65880309848186935 1" mesh="bimanual_insertion_hole3/bimanual_insertion_hole3_collision_34"/>
        <geom name="bimanual_insertion_hole3//unnamed_geom_36" class="bimanual_insertion_hole3/collision" rgba="0.73316113164432928 0.81479651085741844 0.95880367965214908 1" mesh="bimanual_insertion_hole3/bimanual_insertion_hole3_collision_35"/>
        <body name="bimanual_insertion_hole3/bimanual_insertion_hole3_axis" pos="0 0 0">
          <geom name="bimanual_insertion_hole3//unnamed_geom_37" class="bimanual_insertion_hole3/" type="box" contype="0" conaffinity="0" group="5" size="0.029999999999999999 0.029999999999999999 0.029999999999999999" rgba="0.59999999999999998 0.29999999999999999 0.29999999999999999 0.5"/>
          <geom name="bimanual_insertion_hole3//unnamed_geom_38" class="bimanual_insertion_hole3/" type="box" contype="0" conaffinity="0" group="5" size="0.059999999999999998 0.002 0.002" rgba="1 0 0 0.5" pos="0.059999999999999998 0 0"/>
          <geom name="bimanual_insertion_hole3//unnamed_geom_39" class="bimanual_insertion_hole3/" type="box" contype="0" conaffinity="0" group="5" size="0.002 0.059999999999999998 0.002" rgba="0 1 0 0.5" pos="0 0.059999999999999998 0"/>
          <geom name="bimanual_insertion_hole3//unnamed_geom_40" class="bimanual_insertion_hole3/" type="box" contype="0" conaffinity="0" group="5" size="0.002 0.002 0.059999999999999998" rgba="0 0 1 0.5" pos="0 0 0.059999999999999998"/>
        </body>
      </body>
    </body>
    <camera name="main_front" class="/" fovy="70" pos="-0 0.80000000000000004 0.81899999999999995" xyaxes="-1 -0 -0 0.0080000000000000002 -1 1"/>
  </worldbody>
  <equality>
    <joint name="l_robot//unnamed_equality_0" class="l_robot/" solref="0.0050000000000000001 1" solimp="0.94999999999999996 0.98999999999999999 0.001" joint1="l_robot/finger_joint1" joint2="l_robot/finger_joint2"/>
    <joint name="r_robot//unnamed_equality_0" class="r_robot/" solref="0.0050000000000000001 1" solimp="0.94999999999999996 0.98999999999999999 0.001" joint1="r_robot/finger_joint1" joint2="r_robot/finger_joint2"/>
  </equality>
  <tendon>
    <fixed name="l_robot/split" class="l_robot/">
      <joint joint="l_robot/finger_joint1" coef="0.5"/>
      <joint joint="l_robot/finger_joint2" coef="0.5"/>
    </fixed>
    <fixed name="r_robot/split" class="r_robot/">
      <joint joint="r_robot/finger_joint1" coef="0.5"/>
      <joint joint="r_robot/finger_joint2" coef="0.5"/>
    </fixed>
  </tendon>
  <actuator>
    <general name="l_robot/actuator1" class="l_robot/panda" joint="l_robot/joint1" gainprm="4500" biasprm="0 -4500 -450"/>
    <general name="l_robot/actuator2" class="l_robot/panda" ctrlrange="-1.7627999999999999 1.7627999999999999" joint="l_robot/joint2" gainprm="4500" biasprm="0 -4500 -450"/>
    <general name="l_robot/actuator3" class="l_robot/panda" joint="l_robot/joint3" gainprm="3500" biasprm="0 -3500 -350"/>
    <general name="l_robot/actuator4" class="l_robot/panda" ctrlrange="-3.0718000000000001 -0.069800000000000001" joint="l_robot/joint4" gainprm="3500" biasprm="0 -3500 -350"/>
    <general name="l_robot/actuator5" class="l_robot/panda" forcerange="-12 12" joint="l_robot/joint5" gainprm="2000" biasprm="0 -2000 -200"/>
    <general name="l_robot/actuator6" class="l_robot/panda" ctrlrange="-0.017500000000000002 3.7524999999999999" forcerange="-12 12" joint="l_robot/joint6" gainprm="2000" biasprm="0 -2000 -200"/>
    <general name="l_robot/actuator7" class="l_robot/panda" forcerange="-12 12" joint="l_robot/joint7" gainprm="2000" biasprm="0 -2000 -200"/>
    <position name="l_robot//unnamed_actuator_7" class="l_robot/" ctrlrange="0 0.040000000000000001" joint="l_robot/finger_joint1" kp="10000" kv="1000"/>
    <general name="r_robot/actuator1" class="r_robot/panda" joint="r_robot/joint1" gainprm="4500" biasprm="0 -4500 -450"/>
    <general name="r_robot/actuator2" class="r_robot/panda" ctrlrange="-1.7627999999999999 1.7627999999999999" joint="r_robot/joint2" gainprm="4500" biasprm="0 -4500 -450"/>
    <general name="r_robot/actuator3" class="r_robot/panda" joint="r_robot/joint3" gainprm="3500" biasprm="0 -3500 -350"/>
    <general name="r_robot/actuator4" class="r_robot/panda" ctrlrange="-3.0718000000000001 -0.069800000000000001" joint="r_robot/joint4" gainprm="3500" biasprm="0 -3500 -350"/>
    <general name="r_robot/actuator5" class="r_robot/panda" forcerange="-12 12" joint="r_robot/joint5" gainprm="2000" biasprm="0 -2000 -200"/>
    <general name="r_robot/actuator6" class="r_robot/panda" ctrlrange="-0.017500000000000002 3.7524999999999999" forcerange="-12 12" joint="r_robot/joint6" gainprm="2000" biasprm="0 -2000 -200"/>
    <general name="r_robot/actuator7" class="r_robot/panda" forcerange="-12 12" joint="r_robot/joint7" gainprm="2000" biasprm="0 -2000 -200"/>
    <position name="r_robot//unnamed_actuator_7" class="r_robot/" ctrlrange="0 0.040000000000000001" joint="r_robot/finger_joint1" kp="10000" kv="1000"/>
  </actuator>
  <keyframe>
    <key name="home" time="0" qpos="0 0 0 -1.5707899999999999 0 1.5707899999999999 -0.7853 0.040000000000000001 0.040000000000000001 0 0 0 -1.5707899999999999 0 1.5707899999999999 -0.7853 0.040000000000000001 0.040000000000000001 0 0.29999999999999999 0.10000000000000001 1 0 0 0 0 0.10000000000000001 0.10000000000000001 1 0 0 0"/>
  </keyframe>
</mujoco>
